<?xml version="1.0" ?>
<robot
  name="hubo_head_description">
  <link
    name="head_base_link">
    <inertial>
      <origin
        xyz="2.3304978183754E-18 -4.99430308017913E-19 0.00499999999999999"
        rpy="0 0 0" />
      <mass
        value="0.0222146018366026" />
      <inertia
        ixx="3.12556116400805E-06"
        ixy="-3.6189151799195E-22"
        ixz="-7.38039080574315E-24"
        iyy="6.70889449734138E-06"
        iyz="-6.4074231160126E-22"
        izz="9.46421229740605E-06" />
    </inertial>
    <visual>
      <origin
        xyz="0 0 0"
        rpy="0 0 0" />
      <geometry>
        <mesh
          filename="package://hubo_head_description/meshes/head_base_link.STL" />
      </geometry>
      <material
        name="">
        <color
          rgba="0.792156862745098 0.819607843137255 0.933333333333333 1" />
      </material>
    </visual>
    <collision>
      <origin
        xyz="0 0 0"
        rpy="0 0 0" />
      <geometry>
        <mesh
          filename="package://hubo_head_description/meshes/head_base_link.STL" />
      </geometry>
    </collision>
  </link>
  <link
    name="turret_pan_link">
    <inertial>
      <origin
        xyz="-0.0121822334071311 2.70384781147317E-06 0.0433637013389467"
        rpy="0 0 0" />
      <mass
        value="0.111664559813447" />
      <inertia
        ixx="7.85176777304885E-05"
        ixy="9.83689607173052E-10"
        ixz="9.58070869887956E-06"
        iyy="7.70484870395042E-05"
        iyz="7.18576738195685E-11"
        izz="6.84694193153644E-05" />
    </inertial>
    <visual>
      <origin
        xyz="0 0 0"
        rpy="0 0 0" />
      <geometry>
        <mesh
          filename="package://hubo_head_description/meshes/turret_pan_link.STL" />
      </geometry>
      <material
        name="">
        <color
          rgba="0.792156862745098 0.819607843137255 0.933333333333333 1" />
      </material>
    </visual>
    <collision>
      <origin
        xyz="0 0 0"
        rpy="0 0 0" />
      <geometry>
        <mesh
          filename="package://hubo_head_description/meshes/turret_pan_link.STL" />
      </geometry>
    </collision>
  </link>
  <joint
    name="turret_pan"
    type="continuous">
    <origin
      xyz="0 0 0"
      rpy="0 0 0" />
    <parent
      link="head_base_link" />
    <child
      link="turret_pan_link" />
    <axis
      xyz="0 0 1" />
  </joint>
  <link
    name="turret_tilt_link">
    <inertial>
      <origin
        xyz="-0.00734470869783893 -0.000922567349659617 0.0676763329728171"
        rpy="0 0 0" />
      <mass
        value="0.953306948960365" />
      <inertia
        ixx="0.00469179439631725"
        ixy="0.000196132307637545"
        ixz="-0.000470692746776285"
        iyy="0.00388386160583068"
        iyz="0.000254653139531593"
        izz="0.00321268464679288" />
    </inertial>
    <visual>
      <origin
        xyz="0 0 0"
        rpy="0 0 0" />
      <geometry>
        <mesh
          filename="package://hubo_head_description/meshes/turret_tilt_link.STL" />
      </geometry>
      <material
        name="">
        <color
          rgba="0.866666666666667 0.909803921568627 1 1" />
      </material>
    </visual>
    <collision>
      <origin
        xyz="0 0 0"
        rpy="0 0 0" />
      <geometry>
        <mesh
          filename="package://hubo_head_description/meshes/turret_tilt_link.STL" />
      </geometry>
    </collision>
  </link>
  <joint
    name="turret_tilt"
    type="continuous">
    <origin
      xyz="0 0 0.081"
      rpy="0 0 0" />
    <parent
      link="turret_pan_link" />
    <child
      link="turret_tilt_link" />
    <axis
      xyz="0 1 0" />
  </joint>
  <link
    name="lidar_tilt_link">
    <inertial>
      <origin
        xyz="-0.000451739713036539 0.00142068072982725 0.0095378406254539"
        rpy="0 0 0" />
      <mass
        value="0.277440816169479" />
      <inertia
        ixx="0.000287641113004078"
        ixy="-2.12281230788968E-07"
        ixz="-2.79974835499033E-07"
        iyy="0.000278108111077794"
        iyz="-5.64059773108329E-07"
        izz="0.000168611601516652" />
    </inertial>
    <visual>
      <origin
        xyz="0 0 0"
        rpy="0 0 0" />
      <geometry>
        <mesh
          filename="package://hubo_head_description/meshes/lidar_tilt_link.STL" />
      </geometry>
      <material
        name="">
        <color
          rgba="0 0 0 1" />
      </material>
    </visual>
    <collision>
      <origin
        xyz="0 0 0"
        rpy="0 0 0" />
      <geometry>
        <mesh
          filename="package://hubo_head_description/meshes/lidar_tilt_link.STL" />
      </geometry>
    </collision>
  </link>
  <joint
    name="lidar_tilt"
    type="continuous">
    <origin
      xyz="0.062 0 0.03636"
      rpy="0 0 0" />
    <parent
      link="turret_tilt_link" />
    <child
      link="lidar_tilt_link" />
    <axis
      xyz="0 1 0" />
  </joint>
  <link
    name="lidar_optical_frame" />
  <joint
    name="lidar_optical_link"
    type="fixed">
    <origin
      xyz="0 0.00134999999999998 0.032"
      rpy="0 0 0" />
    <parent
      link="lidar_tilt_link" />
    <child
      link="lidar_optical_frame" />
    <axis
      xyz="0 0 0" />
  </joint>
  <link
    name="camera_l_link">
    <inertial>
      <origin
        xyz="0.00514229232434571 3.13965923078446E-05 -0.000183606189112423"
        rpy="0 0 0" />
      <mass
        value="0.059130842653584" />
      <inertia
        ixx="8.2699233854617E-06"
        ixy="-7.22497182350792E-08"
        ixz="6.15615294955095E-07"
        iyy="4.27928696441055E-05"
        iyz="1.26762308242955E-08"
        izz="4.2762321740079E-05" />
    </inertial>
    <visual>
      <origin
        xyz="0 0 0"
        rpy="0 0 0" />
      <geometry>
        <mesh
          filename="package://hubo_head_description/meshes/flea_camera.STL" />
      </geometry>
      <material
        name="">
        <color
          rgba="0.752941176470588 0.752941176470588 0.752941176470588 1" />
      </material>
    </visual>
    <collision>
      <origin
        xyz="0 0 0"
        rpy="0 0 0" />
      <geometry>
        <mesh
          filename="package://hubo_head_description/meshes/flea_camera.STL" />
      </geometry>
    </collision>
  </link>
  <joint
    name="camera_l"
    type="fixed">
    <origin
      xyz="0.040455 0.088675 0.14036"
      rpy="0 0 0" />
    <parent
      link="turret_tilt_link" />
    <child
      link="camera_l_link" />
    <axis
      xyz="0 0 0" />
  </joint>
  <link
    name="camera_c_link">
    <inertial>
      <origin
        xyz="0.00514229222132032 3.13965917268962E-05 -0.000183606196061697"
        rpy="0 0 0" />
      <mass
        value="0.0591308427749407" />
      <inertia
        ixx="8.26992338690152E-06"
        ixy="-7.22497165061013E-08"
        ixz="6.15615315572638E-07"
        iyy="4.27928699512976E-05"
        iyz="1.26762309361678E-08"
        izz="4.276232204585E-05" />
    </inertial>
    <visual>
      <origin
        xyz="0 0 0"
        rpy="0 0 0" />
      <geometry>
        <mesh
          filename="package://hubo_head_description/meshes/flea_camera.STL" />
      </geometry>
      <material
        name="">
        <color
          rgba="0.752941176470588 0.752941176470588 0.752941176470588 1" />
      </material>
    </visual>
    <collision>
      <origin
        xyz="0 0 0"
        rpy="0 0 0" />
      <geometry>
        <mesh
          filename="package://hubo_head_description/meshes/flea_camera.STL" />
      </geometry>
    </collision>
  </link>
  <joint
    name="camera_c"
    type="fixed">
    <origin
      xyz="0.040455 0.028675 0.14036"
      rpy="0 0 0" />
    <parent
      link="turret_tilt_link" />
    <child
      link="camera_c_link" />
    <axis
      xyz="0 0 0" />
  </joint>
  <link
    name="camera_r_link">
    <inertial>
      <origin
        xyz="0.00514229219892091 3.13965916506204E-05 -0.000183606197523695"
        rpy="0 0 0" />
      <mass
        value="0.0591308428004722" />
      <inertia
        ixx="8.26992338720286E-06"
        ixy="-7.22497162707901E-08"
        ixz="6.15615320049058E-07"
        iyy="4.2792870020323E-05"
        iyz="1.26762309508922E-08"
        izz="4.27623221145749E-05" />
    </inertial>
    <visual>
      <origin
        xyz="0 0 0"
        rpy="0 0 0" />
      <geometry>
        <mesh
          filename="package://hubo_head_description/meshes/flea_camera.STL" />
      </geometry>
      <material
        name="">
        <color
          rgba="0.752941176470588 0.752941176470588 0.752941176470588 1" />
      </material>
    </visual>
    <collision>
      <origin
        xyz="0 0 0"
        rpy="0 0 0" />
      <geometry>
        <mesh
          filename="package://hubo_head_description/meshes/flea_camera.STL" />
      </geometry>
    </collision>
  </link>
  <joint
    name="camera_r"
    type="fixed">
    <origin
      xyz="0.040455 -0.091325 0.14036"
      rpy="0 0 0" />
    <parent
      link="turret_tilt_link" />
    <child
      link="camera_r_link" />
    <axis
      xyz="0 0 0" />
  </joint>
  <link
    name="ps_lower_base_link" />
  <joint
    name="ps_lower_base"
    type="fixed">
    <origin
      xyz="-0.067789086884583 -0.00132499999999999 0.120355390601482"
      rpy="8.13589349446095E-16 0.747175452778788 -3.14159265358979" />
    <parent
      link="turret_tilt_link" />
    <child
      link="ps_lower_base_link" />
    <axis
      xyz="0 0 0" />
  </joint>
  <link
    name="ps_upper_base_link" />
  <joint
    name="ps_upper_base"
    type="fixed">
    <origin
      xyz="-0.068045 -0.00132499999999995 0.170176213379847"
      rpy="5.96858314644388E-16 1.04083408558608E-15 3.14159265358979" />
    <parent
      link="turret_tilt_link" />
    <child
      link="ps_upper_base_link" />
    <axis
      xyz="0 0 0" />
  </joint>
</robot>
