<?xml version="1.0" ?>
<robot name="hubo_kart_display_v1">

<link name="hubo_base">
    <visual>
      <geometry>
        <cylinder length="0.0" radius="0.0"/>
      </geometry>
    </visual>
  </link>


    <link name="Body_TSY">
        <visual>
            <geometry>
                <mesh filename="package://hubo_kart_display_v1/meshes/convhull_TSY_merged.stl"/>
            </geometry>
            <origin rpy="0 0 0" xyz="0 0 0"/>
            <material name="">
                <color rgba="0.752941176471 0.752941176471 0.752941176471 1.0"/>
            </material>
        </visual>
        <collision>
            <geometry>
                <mesh filename="package://hubo_kart_display_v1/meshes/convhull_TSY_merged.stl"/>
            </geometry>
            <origin rpy="0 0 0" xyz="0 0 0"/>
        </collision>
        <inertial>
            <mass value="4.83018847366"/>
            <inertia ixx="0.0242710547439" ixy="4.03308627246e-06" ixz="0.000107562017398" iyy="0.0103772739035" iyz="1.38922193141e-06" izz="0.0286360929382"/>
            <origin rpy="0 0 0" xyz="-0.0172313454531 7.7473414697e-06 -0.032639940662"/>
        </inertial>
    </link>


<joint name="hubo_move" type="planar">
        <parent link="hubo_base"/>
        <child link="Body_TSY"/>
        <origin rpy="0 0 0" xyz="0.0 0 0.0"/>
        <axis xyz="0 0 1.0"/>
         <limit effort="25" lower="-1.06813521904" upper="1.06814778541" velocity="6.28318530718"/>
    </joint>
    <link name="Body_Torso">
        <visual>
            <geometry>
                <mesh filename="package://hubo_kart_display_v1/meshes/convhull_Torso_merged.stl"/>
            </geometry>
            <origin rpy="0 0 0" xyz="0 0 0"/>
            <material name="">
                <color rgba="0.752941176471 0.752941176471 0.752941176471 1.0"/>
            </material>
        </visual>
        <collision>
            <geometry>
                <mesh filename="package://hubo_kart_display_v1/meshes/convhull_Torso_merged.stl"/>
            </geometry>
            <origin rpy="0 0 0" xyz="0 0 0"/>
        </collision>
        <inertial>
            <mass value="12.0205278528"/>
            <inertia ixx="0.139304186385" ixy="3.94986545913e-06" ixz="-0.00823717402835" iyy="0.103349048038" iyz="-5.51332752869e-06" izz="0.138503173371"/>
            <origin rpy="0 0 0" xyz="-0.00653576137697 2.64726276972e-05 -0.0481158946001"/>
        </inertial>
    </link>
    <joint name="TSY" type="revolute">
        <parent link="Body_TSY"/>
        <child link="Body_Torso"/>
        <origin rpy="0 0 0" xyz="0.00099991 0 0.2061"/>
        <axis xyz="0 0 1.0"/>
        <limit effort="25" lower="-1.06813521904" upper="1.06814778541" velocity="6.28318530718"/>
    </joint>
    <link name="Body_RHY">
        <visual>
            <geometry>
                <mesh filename="package://hubo_kart_display_v1/meshes/convhull_RHY_merged.stl"/>
            </geometry>
            <origin rpy="0 0 0" xyz="0 0 0"/>
            <material name="">
                <color rgba="0.752941176471 0.752941176471 0.752941176471 1.0"/>
            </material>
        </visual>
        <collision>
            <geometry>
                <mesh filename="package://hubo_kart_display_v1/meshes/convhull_RHY_merged.stl"/>
            </geometry>
            <origin rpy="0 0 0" xyz="0 0 0"/>
        </collision>
        <inertial>
            <mass value="1.39676631505"/>
            <inertia ixx="0.00288796936083" ixy="9.31467192308e-07" ixz="-0.00107856005839" iyy="0.00475787075044" iyz="-1.27885368145e-06" izz="0.0030062595856"/>
            <origin rpy="0 0 0" xyz="0.0357455188333 -9.87014023897e-06 -0.0612768789732"/>
        </inertial>
    </link>
    <joint name="RHY" type="revolute">
        <parent link="Body_TSY"/>
        <child link="Body_RHY"/>
        <origin rpy="0 0 0" xyz="0 -0.0885 -0.0751"/>
        <axis xyz="0 0 1.0"/>
        <limit effort="25" lower="-2.38760413354" upper="1.57080260998" velocity="6.28318530718"/>
    </joint>
    <link name="Body_RHR">
        <visual>
            <geometry>
                <mesh filename="package://hubo_kart_display_v1/meshes/convhull_RHR_merged.stl"/>
            </geometry>
            <origin rpy="0 0 0" xyz="0 0 0"/>
            <material name="">
                <color rgba="0.752941176471 0.752941176471 0.752941176471 1.0"/>
            </material>
        </visual>
        <collision>
            <geometry>
                <mesh filename="package://hubo_kart_display_v1/meshes/convhull_RHR_merged.stl"/>
            </geometry>
            <origin rpy="0 0 0" xyz="0 0 0"/>
        </collision>
        <inertial>
            <mass value="1.87327014692"/>
            <inertia ixx="0.00271708242471" ixy="6.95355289452e-06" ixz="-0.000124506400405" iyy="0.00314352531524" iyz="-0.000179044888416" izz="0.00241624814317"/>
            <origin rpy="0 0 0" xyz="-0.0546751887964 0.000755923439321 -0.0250478918092"/>
        </inertial>
    </link>
    <joint name="RHR" type="revolute">
        <parent link="Body_RHY"/>
        <child link="Body_RHR"/>
        <origin rpy="0 0 0" xyz="0.052 0 -0.091"/>
        <axis xyz="1.0 0 0"/>
        <limit effort="25" lower="-0.559132890873" upper="0.372760437767" velocity="6.28318530718"/>
    </joint>
    <link name="Body_RHP">
        <visual>
            <geometry>
                <mesh filename="package://hubo_kart_display_v1/meshes/convhull_RHP_merged.stl"/>
            </geometry>
            <origin rpy="0 0 0" xyz="0 0 0"/>
            <material name="">
                <color rgba="0.752941176471 0.752941176471 0.752941176471 1.0"/>
            </material>
        </visual>
        <collision>
            <geometry>
                <mesh filename="package://hubo_kart_display_v1/meshes/convhull_RHP_merged.stl"/>
            </geometry>
            <origin rpy="0 0 0" xyz="0 0 0"/>
        </collision>
        <inertial>
            <mass value="4.08210586511"/>
            <inertia ixx="0.0731344926009" ixy="0.000774522574823" ixz="-0.00133507444321" iyy="0.0704116135206" iyz="-0.0038008172567" izz="0.0104352186397"/>
            <origin rpy="0 0 0" xyz="0.014307872736 0.0329553894437 -0.191508079337"/>
        </inertial>
    </link>
    <joint name="RHP" type="revolute">
        <parent link="Body_RHR"/>
        <child link="Body_RHP"/>
        <origin rpy="0 0 0" xyz="-0.052 -0.0445 0"/>
        <axis xyz="0 1.0 0"/>
        <limit effort="25" lower="-1.88157052607" upper="1.57418139288" velocity="6.28318530718"/>
    </joint>
    <link name="Body_RKP">
        <visual>
            <geometry>
                <mesh filename="package://hubo_kart_display_v1/meshes/convhull_RKP_merged.stl"/>
            </geometry>
            <origin rpy="0 0 0" xyz="0 0 0"/>
            <material name="">
                <color rgba="0.75294 0.75294 0.75294 1.0"/>
            </material>
        </visual>
        <collision>
            <geometry>
                <mesh filename="package://hubo_kart_display_v1/meshes/convhull_RKP_merged.stl"/>
            </geometry>
            <origin rpy="0 0 0" xyz="0 0 0"/>
        </collision>
        <inertial>
            <mass value="1.5575"/>
            <inertia ixx="0.023902" ixy="-0.00016341" ixz="0.0003317" iyy="0.021931" iyz="-0.00047965" izz="0.0043485"/>
            <origin rpy="0 0 0" xyz="0.015377 0.023243 -0.16683"/>
        </inertial>
    </link>
    <joint name="RKP" type="revolute">
        <parent link="Body_RHP"/>
        <child link="Body_RKP"/>
        <origin rpy="0 0 0" xyz="0 0.0285 -0.33"/>
        <axis xyz="0 1.0 0"/>
        <limit effort="25" lower="-0.765758104224" upper="2.70570177799" velocity="6.28318530718"/>
    </joint>
    <link name="Body_RAP">
        <visual>
            <geometry>
                <mesh filename="package://hubo_kart_display_v1/meshes/convhull_RAP_merged.stl"/>
            </geometry>
            <origin rpy="0 0 0" xyz="0 0 0"/>
            <material name="">
                <color rgba="0.752941176471 0.752941176471 0.752941176471 1.0"/>
            </material>
        </visual>
        <collision>
            <geometry>
                <mesh filename="package://hubo_kart_display_v1/meshes/convhull_RAP_merged.stl"/>
            </geometry>
            <origin rpy="0 0 0" xyz="0 0 0"/>
        </collision>
        <inertial>
            <mass value="2.28752729358"/>
            <inertia ixx="0.00372279383771" ixy="0.000408405026298" ixz="-0.000324861356781" iyy="0.00395779600552" iyz="0.000345535189408" izz="0.00437930917038"/>
            <origin rpy="0 0 0" xyz="0.015517139691 0.0515086693793 0.00905289185767"/>
        </inertial>
    </link>
    <joint name="RAP" type="revolute">
        <parent link="Body_RKP"/>
        <child link="Body_RAP"/>
        <origin rpy="0 0 0" xyz="0 -0.047 -0.33"/>
        <axis xyz="0 1.0 0"/>
        <limit effort="25" lower="-1.64354304628" upper="2.25203184417" velocity="6.28318530718"/>
    </joint>
    <link name="Body_RAR">
        <visual>
            <geometry>
                <mesh filename="package://hubo_kart_display_v1/meshes/convhull_RAR_merged.stl"/>
            </geometry>
            <origin rpy="0 0 0" xyz="0 0 0"/>
            <material name="">
                <color rgba="0.75294 0.75294 0.75294 1.0"/>
            </material>
        </visual>
        <collision>
            <geometry>
                <mesh filename="package://hubo_kart_display_v1/meshes/convhull_RAR_merged.stl"/>
            </geometry>
            <origin rpy="0 0 0" xyz="0 0 0"/>
        </collision>
        <inertial>
            <mass value="1.173"/>
            <inertia ixx="0.0040657" ixy="-3.062e-05" ixz="-0.0002436" iyy="0.0066321" iyz="0.00010311" izz="0.00448"/>
            <origin rpy="0 0 0" xyz="-0.053052 -0.0019082 -0.093274"/>
        </inertial>
    </link>
    <joint name="RAR" type="revolute">
        <parent link="Body_RAP"/>
        <child link="Body_RAR"/>
        <origin rpy="0 0 0" xyz="0.0705 0.063 0"/>
        <axis xyz="1.0 0 0"/>
        <limit effort="25" lower="-1.73952924336" upper="1.73953918356" velocity="6.28318530718"/>
    </joint>
    <link name="rightFoot">
        <inertial>
            <mass value="0.1"/>
            <inertia ixx="0.0001" ixy="0" ixz="0" iyy="0.0001" iyz="0" izz="0.0001"/>
            <origin rpy="0 0 0" xyz="0 0 0"/>
        </inertial>
    </link>
    <joint name="RAR_dummy" type="fixed">
        <parent link="Body_RAR"/>
        <child link="rightFoot"/>
        <origin rpy="0 0 0" xyz="0 0 -0.1371"/>
    </joint>
    <link name="Body_RSP">
        <visual>
            <geometry>
                <mesh filename="package://hubo_kart_display_v1/meshes/convhull_RSP_merged.stl"/>
            </geometry>
            <origin rpy="0 0 0" xyz="0 0 0"/>
            <material name="">
                <color rgba="0.752941176471 0.752941176471 0.752941176471 1.0"/>
            </material>
        </visual>
        <collision>
            <geometry>
                <mesh filename="package://hubo_kart_display_v1/meshes/convhull_RSP_merged.stl"/>
            </geometry>
            <origin rpy="0 0 0" xyz="0 0 0"/>
        </collision>
        <inertial>
            <mass value="0.925752239669"/>
            <inertia ixx="0.00168445461162" ixy="-0.000340206078138" ixz="-6.31660338214e-06" iyy="0.00157378126325" iyz="7.95927300515e-06" izz="0.00244770101015"/>
            <origin rpy="0 0 0" xyz="0.0211206130677 -0.0669651647046 0.000177534129465"/>
        </inertial>
    </link>
    <joint name="RSP" type="revolute">
        <parent link="Body_Torso"/>
        <child link="Body_RSP"/>
        <origin rpy="0 0 0" xyz="0 -0.1435 0"/>
        <axis xyz="0 1.0 0"/>
        <limit effort="25" lower="-3.81023666761" upper="3.72958570101" velocity="6.28318530718"/>
    </joint>
    <link name="Body_RSR">
        <visual>
            <geometry>
                <mesh filename="package://hubo_kart_display_v1/meshes/convhull_RSR_merged.stl"/>
            </geometry>
            <origin rpy="0 0 0" xyz="0 0 0"/>
            <material name="">
                <color rgba="0.752941176471 0.752941176471 0.752941176471 1.0"/>
            </material>
        </visual>
        <collision>
            <geometry>
                <mesh filename="package://hubo_kart_display_v1/meshes/convhull_RSR_merged.stl"/>
            </geometry>
            <origin rpy="0 0 0" xyz="0 0 0"/>
        </collision>
        <inertial>
            <mass value="0.772866145701"/>
            <inertia ixx="0.000583426982031" ixy="8.46801592608e-07" ixz="-3.33711094992e-05" iyy="0.000797704704735" iyz="-1.1857891966e-05" izz="0.000561294586058"/>
            <origin rpy="0 0 0" xyz="-0.0375650279693 0.000356075210703 -0.0117791110906"/>
        </inertial>
    </link>
    <joint name="RSR" type="revolute">
        <parent link="Body_RSP"/>
        <child link="Body_RSR"/>
        <origin rpy="0 0 0" xyz="0.033 -0.086 0"/>
        <axis xyz="1.0 0 0"/>
        <limit effort="25" lower="-3.1404773882" upper="0.62943379611" velocity="6.28318530718"/>
    </joint>
    <link name="Body_RSY">
        <visual>
            <geometry>
                <mesh filename="package://hubo_kart_display_v1/meshes/convhull_RSY_merged.stl"/>
            </geometry>
            <origin rpy="0 0 0" xyz="0 0 0"/>
            <material name="">
                <color rgba="0.752941176471 0.752941176471 0.752941176471 1.0"/>
            </material>
        </visual>
        <collision>
            <geometry>
                <mesh filename="package://hubo_kart_display_v1/meshes/convhull_RSY_merged.stl"/>
            </geometry>
            <origin rpy="0 0 0" xyz="0 0 0"/>
        </collision>
        <inertial>
            <mass value="2.05731646102"/>
            <inertia ixx="0.0223084392611" ixy="2.50613568022e-05" ixz="-0.00188493824891" iyy="0.0224224037845" iyz="-0.000332193108806" izz="0.00158588979968"/>
            <origin rpy="0 0 0" xyz="0.00919437021309 0.00191434175871 -0.169537229579"/>
        </inertial>
    </link>
    <joint name="RSY" type="revolute">
        <parent link="Body_RSR"/>
        <child link="Body_RSY"/>
        <origin rpy="0 0 0" xyz="-0.033 0 -0.027"/>
        <axis xyz="0 0 1.0"/>
        <limit effort="25" lower="-2.9161362568" upper="2.88010218907" velocity="6.28318530718"/>
    </joint>
    <link name="Body_REP">
        <visual>
            <geometry>
                <mesh filename="package://hubo_kart_display_v1/meshes/convhull_REP_merged.stl"/>
            </geometry>
            <origin rpy="0 0 0" xyz="0 0 0"/>
            <material name="">
                <color rgba="0.752941176471 0.752941176471 0.752941176471 1.0"/>
            </material>
        </visual>
        <collision>
            <geometry>
                <mesh filename="package://hubo_kart_display_v1/meshes/convhull_REP_merged.stl"/>
            </geometry>
            <origin rpy="0 0 0" xyz="0 0 0"/>
        </collision>
        <inertial>
            <mass value="0.298170328162"/>
            <inertia ixx="0.000394363251821" ixy="1.34384975568e-06" ixz="7.57996574577e-05" iyy="0.000374815280261" iyz="-2.18982902478e-06" izz="0.000273941918371"/>
            <origin rpy="0 0 0" xyz="-0.0244460480201 0.0182798518231 -0.0396913386769"/>
        </inertial>
    </link>
    <joint name="REP" type="revolute">
        <parent link="Body_RSY"/>
        <child link="Body_REP"/>
        <origin rpy="0 0 0" xyz="0.03 -0.019 -0.273"/>
        <axis xyz="0 1.0 0"/>
        <limit effort="25" lower="-2.31515743615" upper="0.692917529657" velocity="6.28318530718"/>
    </joint>
    <link name="Body_RWY">
        <visual>
            <geometry>
                <mesh filename="package://hubo_kart_display_v1/meshes/convhull_RWY_merged.stl"/>
            </geometry>
            <origin rpy="0 0 0" xyz="0 0 0"/>
            <material name="">
                <color rgba="0.752941176471 0.752941176471 0.752941176471 1.0"/>
            </material>
        </visual>
        <collision>
            <geometry>
                <mesh filename="package://hubo_kart_display_v1/meshes/convhull_RWY_merged.stl"/>
            </geometry>
            <origin rpy="0 0 0" xyz="0 0 0"/>
        </collision>
        <inertial>
            <mass value="1.68933309958"/>
            <inertia ixx="0.0176540649275" ixy="3.61034488579e-06" ixz="8.37319577754e-06" iyy="0.0150234017716" iyz="0.00516603192566" izz="0.00331146614296"/>
            <origin rpy="0 0 0" xyz="3.39374071556e-05 -0.0559979630014 -0.151262292453"/>
        </inertial>
    </link>
    <joint name="RWY" type="revolute">
        <parent link="Body_REP"/>
        <child link="Body_RWY"/>
        <origin rpy="0 0 0" xyz="-0.03 0.019 -0.052"/>
        <axis xyz="0 0 1.0"/>
        <limit effort="25" lower="-2.76130286287" upper="2.86214798705" velocity="6.28318530718"/>
    </joint>
    <link name="Body_RWP">
        <visual>
            <geometry>
                <mesh filename="package://hubo_kart_display_v1/meshes/convhull_RWP_merged.stl"/>
            </geometry>
            <origin rpy="0 0 0" xyz="0 0 0"/>
            <material name="">
                <color rgba="0.752941176471 0.752941176471 0.752941176471 1.0"/>
            </material>
        </visual>
        <collision>
            <geometry>
                <mesh filename="package://hubo_kart_display_v1/meshes/convhull_RWP_merged.stl"/>
            </geometry>
            <origin rpy="0 0 0" xyz="0 0 0"/>
        </collision>
        <inertial>
            <mass value="0.327632198289"/>
            <inertia ixx="0.000346968656319" ixy="-5.89262498623e-05" ixz="4.30826482069e-06" iyy="0.00057562979027" iyz="1.25504736046e-06" izz="0.000744124634836"/>
            <origin rpy="0 0 0" xyz="-0.0145320131223 0.0546994779181 -0.000367800192129"/>
        </inertial>
    </link>
    <joint name="RWP" type="revolute">
        <parent link="Body_RWY"/>
        <child link="Body_RWP"/>
        <origin rpy="0 1.57079632679 0" xyz="0 -0.067 -0.2618"/>
        <axis xyz="0 1.0 0"/>
        <limit effort="25" lower="-3.29029994185" upper="2.11323942233" velocity="6.28318530718"/>
    </joint>
    <link name="Body_RWR">
        <visual>
            <geometry>
                <mesh filename="package://hubo_kart_display_v1/meshes/convhull_RWR_merged.stl"/>
            </geometry>
            <origin rpy="0 0 0" xyz="0 0 0"/>
            <material name="">
                <color rgba="0.752941176471 0.752941176471 0.752941176471 1.0"/>
            </material>
        </visual>
        <collision>
            <geometry>
                <mesh filename="package://hubo_kart_display_v1/meshes/convhull_RWR_merged.stl"/>
            </geometry>
            <origin rpy="0 0 0" xyz="0 0 0"/>
        </collision>
        <inertial>
            <mass value="1.26227162553"/>
            <inertia ixx="0.00137019038629" ixy="-6.08173568367e-05" ixz="5.84193124812e-06" iyy="0.00133077281236" iyz="1.17164831963e-05" izz="0.00120357514264"/>
            <origin rpy="0 0 0" xyz="0.0461316332402 0.000476271776753 0.0008021254173"/>
        </inertial>
    </link>
    <joint name="RWR" type="revolute">
        <parent link="Body_RWP"/>
        <child link="Body_RWR"/>
        <origin rpy="0 0 0" xyz="0.027 0.067 0"/>
        <axis xyz="-1.0 0 0"/>
        <limit effort="25" lower="-2.69195220504" upper="2.70766016831" velocity="6.28318530718"/>
    </joint>
    <link name="rightPalm">
        <inertial>
            <mass value="0.1"/>
            <inertia ixx="0.0001" ixy="0" ixz="0" iyy="0.0001" iyz="0" izz="0.0001"/>
            <origin rpy="0 0 0" xyz="0 0 0"/>
        </inertial>
    </link>
    <joint name="RWR_dummy" type="fixed">
        <parent link="Body_RWR"/>
        <child link="rightPalm"/>
        <origin rpy="0 0 -1.57079632679" xyz="0.1 0 0"/>
    </joint>

<link
    name="head_base_link">
    <inertial>
      <origin
        xyz="2.3304978183754E-18 -4.99430308017913E-19 0.00499999999999999"
        rpy="0 0 0" />
      <mass
        value="0.0222146018366026" />
      <inertia
        ixx="3.12556116400805E-06"
        ixy="-3.6189151799195E-22"
        ixz="-7.38039080574315E-24"
        iyy="6.70889449734138E-06"
        iyz="-6.4074231160126E-22"
        izz="9.46421229740605E-06" />
    </inertial>
    <visual>
      <origin
        xyz="0 0 0"
        rpy="0 0 0" />
      <geometry>
        <mesh
          filename="package://hubo_kart_display_v1/meshes/head_base_link.STL" />
      </geometry>
      <material
        name="">
        <color
          rgba="0.792156862745098 0.819607843137255 0.933333333333333 1" />
      </material>
    </visual>
    <collision>
      <origin
        xyz="0 0 0"
        rpy="0 0 0" />
      <geometry>
        <mesh
          filename="package://hubo_kart_display_v1/meshes/head_base_link.STL" />
      </geometry>
    </collision>
  </link>
    

    <joint name="NKY" type="revolute">
        <parent link="Body_Torso"/>
        <child link="head_base_link"/>
        <origin rpy="0 0 0" xyz="0 -1.0274e-05 0.0585"/>
        <axis xyz="0 0 1.0"/>
        <limit effort="25" lower="-3.14159265359" upper="3.14159265359" velocity="6.28318530718"/>
    </joint>

 <link
    name="turret_pan_link">
    <inertial>
      <origin
        xyz="-0.0121822334071311 2.70384781147317E-06 0.0433637013389467"
        rpy="0 0 0" />
      <mass
        value="0.111664559813447" />
      <inertia
        ixx="7.85176777304885E-05"
        ixy="9.83689607173052E-10"
        ixz="9.58070869887956E-06"
        iyy="7.70484870395042E-05"
        iyz="7.18576738195685E-11"
        izz="6.84694193153644E-05" />
    </inertial>
    <visual>
      <origin
        xyz="0 0 0"
        rpy="0 0 0" />
      <geometry>
        <mesh
          filename="package://hubo_kart_display_v1/meshes/turret_pan_link.STL" />
      </geometry>
      <material
        name="">
        <color
          rgba="0.792156862745098 0.819607843137255 0.933333333333333 1" />
      </material>
    </visual>
    <collision>
      <origin
        xyz="0 0 0"
        rpy="0 0 0" />
      <geometry>
        <mesh
          filename="package://hubo_kart_display_v1/meshes/turret_pan_link.STL" />
      </geometry>
    </collision>
  </link>
  <joint
    name="turret_pan"
    type="continuous">
    <origin
      xyz="0 0 0"
      rpy="0 0 0" />
    <parent
      link="head_base_link" />
    <child
      link="turret_pan_link" />
    <axis
      xyz="0 0 1" />
  </joint>
  <link
    name="turret_tilt_link">
    <inertial>
      <origin
        xyz="-0.00734470869783893 -0.000922567349659617 0.0676763329728171"
        rpy="0 0 0" />
      <mass
        value="0.953306948960365" />
      <inertia
        ixx="0.00469179439631725"
        ixy="0.000196132307637545"
        ixz="-0.000470692746776285"
        iyy="0.00388386160583068"
        iyz="0.000254653139531593"
        izz="0.00321268464679288" />
    </inertial>
    <visual>
      <origin
        xyz="0 0 0"
        rpy="0 0 0" />
      <geometry>
        <mesh
          filename="package://hubo_kart_display_v1/meshes/turret_tilt_link.STL" />
      </geometry>
      <material
        name="">
        <color
          rgba="0.866666666666667 0.909803921568627 1 1" />
      </material>
    </visual>
    <collision>
      <origin
        xyz="0 0 0"
        rpy="0 0 0" />
      <geometry>
        <mesh
          filename="package://hubo_kart_display_v1/meshes/turret_tilt_link.STL" />
      </geometry>
    </collision>
  </link>
  <joint
    name="turret_tilt"
    type="continuous">
    <origin
      xyz="0 0 0.081"
      rpy="0 0 0" />
    <parent
      link="turret_pan_link" />
    <child
      link="turret_tilt_link" />
    <axis
      xyz="0 1 0" />
  </joint>
  <link
    name="lidar_tilt_link">
    <inertial>
      <origin
        xyz="-0.000451739713036539 0.00142068072982725 0.0095378406254539"
        rpy="0 0 0" />
      <mass
        value="0.277440816169479" />
      <inertia
        ixx="0.000287641113004078"
        ixy="-2.12281230788968E-07"
        ixz="-2.79974835499033E-07"
        iyy="0.000278108111077794"
        iyz="-5.64059773108329E-07"
        izz="0.000168611601516652" />
    </inertial>
    <visual>
      <origin
        xyz="0 0 0"
        rpy="0 0 0" />
      <geometry>
        <mesh
          filename="package://hubo_kart_display_v1/meshes/lidar_tilt_link.STL" />
      </geometry>
      <material
        name="">
        <color
          rgba="0 0 0 1" />
      </material>
    </visual>
    <collision>
      <origin
        xyz="0 0 0"
        rpy="0 0 0" />
      <geometry>
        <mesh
          filename="package://hubo_kart_display_v1/meshes/lidar_tilt_link.STL" />
      </geometry>
    </collision>
  </link>
  <joint
    name="lidar_tilt"
    type="continuous">
    <origin
      xyz="0.062 0 0.03636"
      rpy="0 0 0" />
    <parent
      link="turret_tilt_link" />
    <child
      link="lidar_tilt_link" />
    <axis
      xyz="0 1 0" />
  </joint>
  <link
    name="lidar_optical_frame" />
  <joint
    name="lidar_optical_link"
    type="fixed">
    <origin
      xyz="0 0.00134999999999998 0.032"
      rpy="0 0 0" />
    <parent
      link="lidar_tilt_link" />
    <child
      link="lidar_optical_frame" />
    <axis
      xyz="0 0 0" />
  </joint>
  <link
    name="camera_l_link">
    <inertial>
      <origin
        xyz="0.00514229232434571 3.13965923078446E-05 -0.000183606189112423"
        rpy="0 0 0" />
      <mass
        value="0.059130842653584" />
      <inertia
        ixx="8.2699233854617E-06"
        ixy="-7.22497182350792E-08"
        ixz="6.15615294955095E-07"
        iyy="4.27928696441055E-05"
        iyz="1.26762308242955E-08"
        izz="4.2762321740079E-05" />
    </inertial>
    <visual>
      <origin
        xyz="0 0 0"
        rpy="0 0 0" />
      <geometry>
        <mesh
          filename="package://hubo_kart_display_v1/meshes/flea_camera.STL" />
      </geometry>
      <material
        name="">
        <color
          rgba="0.752941176470588 0.752941176470588 0.752941176470588 1" />
      </material>
    </visual>
    <collision>
      <origin
        xyz="0 0 0"
        rpy="0 0 0" />
      <geometry>
        <mesh
          filename="package://hubo_kart_display_v1/meshes/flea_camera.STL" />
      </geometry>
    </collision>
  </link>
  <joint
    name="camera_l"
    type="fixed">
    <origin
      xyz="0.040455 0.088675 0.14036"
      rpy="0 0 0" />
    <parent
      link="turret_tilt_link" />
    <child
      link="camera_l_link" />
    <axis
      xyz="0 0 0" />
  </joint>
  <link
    name="camera_c_link">
    <inertial>
      <origin
        xyz="0.00514229222132032 3.13965917268962E-05 -0.000183606196061697"
        rpy="0 0 0" />
      <mass
        value="0.0591308427749407" />
      <inertia
        ixx="8.26992338690152E-06"
        ixy="-7.22497165061013E-08"
        ixz="6.15615315572638E-07"
        iyy="4.27928699512976E-05"
        iyz="1.26762309361678E-08"
        izz="4.276232204585E-05" />
    </inertial>
    <visual>
      <origin
        xyz="0 0 0"
        rpy="0 0 0" />
      <geometry>
        <mesh
          filename="package://hubo_kart_display_v1/meshes/flea_camera.STL" />
      </geometry>
      <material
        name="">
        <color
          rgba="0.752941176470588 0.752941176470588 0.752941176470588 1" />
      </material>
    </visual>
    <collision>
      <origin
        xyz="0 0 0"
        rpy="0 0 0" />
      <geometry>
        <mesh
          filename="package://hubo_kart_display_v1/meshes/flea_camera.STL" />
      </geometry>
    </collision>
  </link>
  <joint
    name="camera_c"
    type="fixed">
    <origin
      xyz="0.040455 0.028675 0.14036"
      rpy="0 0 0" />
    <parent
      link="turret_tilt_link" />
    <child
      link="camera_c_link" />
    <axis
      xyz="0 0 0" />
  </joint>
  <link
    name="camera_r_link">
    <inertial>
      <origin
        xyz="0.00514229219892091 3.13965916506204E-05 -0.000183606197523695"
        rpy="0 0 0" />
      <mass
        value="0.0591308428004722" />
      <inertia
        ixx="8.26992338720286E-06"
        ixy="-7.22497162707901E-08"
        ixz="6.15615320049058E-07"
        iyy="4.2792870020323E-05"
        iyz="1.26762309508922E-08"
        izz="4.27623221145749E-05" />
    </inertial>
    <visual>
      <origin
        xyz="0 0 0"
        rpy="0 0 0" />
      <geometry>
        <mesh
          filename="package://hubo_kart_display_v1/meshes/flea_camera.STL" />
      </geometry>
      <material
        name="">
        <color
          rgba="0.752941176470588 0.752941176470588 0.752941176470588 1" />
      </material>
    </visual>
    <collision>
      <origin
        xyz="0 0 0"
        rpy="0 0 0" />
      <geometry>
        <mesh
          filename="package://hubo_kart_display_v1/meshes/flea_camera.STL" />
      </geometry>
    </collision>
  </link>
  <joint
    name="camera_r"
    type="fixed">
    <origin
      xyz="0.040455 -0.091325 0.14036"
      rpy="0 0 0" />
    <parent
      link="turret_tilt_link" />
    <child
      link="camera_r_link" />
    <axis
      xyz="0 0 0" />
  </joint>
  <link
    name="ps_lower_base_link" />
  <joint
    name="ps_lower_base"
    type="fixed">
    <origin
      xyz="-0.067789086884583 -0.00132499999999999 0.120355390601482"
      rpy="8.13589349446095E-16 0.747175452778788 -3.14159265358979" />
    <parent
      link="turret_tilt_link" />
    <child
      link="ps_lower_base_link" />
    <axis
      xyz="0 0 0" />
  </joint>
  <link
    name="ps_upper_base_link" />
  <joint
    name="ps_upper_base"
    type="fixed">
    <origin
      xyz="-0.068045 -0.00132499999999995 0.170176213379847"
      rpy="5.96858314644388E-16 1.04083408558608E-15 3.14159265358979" />
    <parent
      link="turret_tilt_link" />
    <child
      link="ps_upper_base_link" />
    <axis
      xyz="0 0 0" />
  </joint>


       
    <link name="Body_RF41">
        <visual>
            <geometry>
                <mesh filename="package://hubo_kart_display_v1/meshes/convhull_RF11.stl"/>
            </geometry>
            <origin rpy="0 0 0" xyz="0 0 0"/>
            <material name="">
                <color rgba="0.752941176471 0.752941176471 0.752941176471 1.0"/>
            </material>
        </visual>
        <collision>
            <geometry>
                <mesh filename="package://hubo_kart_display_v1/meshes/convhull_RF11.stl"/>
            </geometry>
            <origin rpy="0 0 0" xyz="0 0 0"/>
        </collision>
        <inertial>
            <mass value="0.0263710561485"/>
            <inertia ixx="1.98396452599e-06" ixy="3.66951887147e-08" ixz="-7.82216984076e-08" iyy="6.90160003554e-06" iyz="-5.52885002718e-09" izz="6.59611728997e-06"/>
            <origin rpy="0 0 0" xyz="0.0136755315275 0.0001676659415 0.000198749354248"/>
        </inertial>
    </link>
    <joint name="RF2" type="revolute">
        <parent link="Body_RWR"/>
        <child link="Body_RF41"/>
        <origin rpy="-1.5708 0 0" xyz="0.0875 0.026 0.0445"/>
        <axis xyz="0 0 -1.0"/>
        <limit effort="25" lower="-1.91728423726" upper="0" velocity="6.28318530718"/>
    </joint>
    <link name="Body_RF42">
        <visual>
            <geometry>
                <mesh filename="package://hubo_kart_display_v1/meshes/convhull_RF12_merged.stl"/>
            </geometry>
            <origin rpy="0 0 0" xyz="0 0 0"/>
            <material name="">
                <color rgba="0.752941176471 0.752941176471 0.752941176471 1.0"/>
            </material>
        </visual>
        <collision>
            <geometry>
                <mesh filename="package://hubo_kart_display_v1/meshes/convhull_RF12_merged.stl"/>
            </geometry>
            <origin rpy="0 0 0" xyz="0 0 0"/>
        </collision>
        <inertial>
            <mass value="0.016189368249"/>
            <inertia ixx="1.30911370818e-06" ixy="1.49423602565e-08" ixz="-5.01486524729e-08" iyy="2.82043860524e-06" iyz="-2.8629444527e-09" izz="3.05888536891e-06"/>
            <origin rpy="0 0 0" xyz="0.0110393059886 0.000234060880175 5.56986057552e-05"/>
        </inertial>
    </link>
    <joint name="RF42" type="revolute">
        <parent link="Body_RF41"/>
        <child link="Body_RF42"/>
        <origin rpy="0 1.3963 0" xyz="0.041952 0 -0.002"/>
        <axis xyz="0 1.0 0"/>
        <limit effort="25" lower="-3.14159265359" upper="3.14159265359" velocity="6.28318530718"/>
    </joint>
    <link name="Body_RF43">
        <visual>
            <geometry>
                <mesh filename="package://hubo_kart_display_v1/meshes/convhull_RF13_merged.stl"/>
            </geometry>
            <origin rpy="0 0 0" xyz="0 0 0"/>
            <material name="">
                <color rgba="0.752941176471 0.752941176471 0.752941176471 1.0"/>
            </material>
        </visual>
        <collision>
            <geometry>
                <mesh filename="package://hubo_kart_display_v1/meshes/convhull_RF13_merged.stl"/>
            </geometry>
            <origin rpy="0 0 0" xyz="0 0 0"/>
        </collision>
        <inertial>
            <mass value="0.0182221650877"/>
            <inertia ixx="1.03181617487e-06" ixy="-4.94978359879e-08" ixz="-1.22492186704e-07" iyy="2.57254536616e-06" iyz="-5.58418574878e-09" izz="2.54656084717e-06"/>
            <origin rpy="0 0 0" xyz="0.0171497739791 -0.000431859131656 0.000224831410368"/>
        </inertial>
    </link>
    <joint name="RF43" type="revolute">
        <parent link="Body_RF42"/>
        <child link="Body_RF43"/>
        <origin rpy="0 1.3963 0" xyz="0.029967 0 -0.0014"/>
        <axis xyz="0 1.0 0"/>
        <limit effort="25" lower="-3.14159265359" upper="3.14159265359" velocity="6.28318530718"/>
    </joint>
    <link name="Body_RF11">
        <visual>
            <geometry>
                <mesh filename="package://hubo_kart_display_v1/meshes/convhull_RF11.stl"/>
            </geometry>
            <origin rpy="0 0 0" xyz="0 0 0"/>
            <material name="">
                <color rgba="0.752941176471 0.752941176471 0.752941176471 1.0"/>
            </material>
        </visual>
        <collision>
            <geometry>
                <mesh filename="package://hubo_kart_display_v1/meshes/convhull_RF11.stl"/>
            </geometry>
            <origin rpy="0 0 0" xyz="0 0 0"/>
        </collision>
        <inertial>
            <mass value="0.0263710648328"/>
            <inertia ixx="1.98396439062e-06" ixy="3.66951330319e-08" ixz="-7.82216813087e-08" iyy="6.90160086478e-06" iyz="-5.52885566501e-09" izz="6.59611827284e-06"/>
            <origin rpy="0 0 0" xyz="0.013675535045 0.000167665760228 0.000198749511991"/>
        </inertial>
    </link>
    <joint name="RF1" type="revolute">
        <parent link="Body_RWR"/>
        <child link="Body_RF11"/>
        <origin rpy="1.5708 0 0" xyz="0.0875 -0.026 0.02247"/>
        <axis xyz="0 0 1.0"/>
        <limit effort="25" lower="-1.85349620283" upper="0.2" velocity="6.28318530718"/>
    </joint>
    <link name="Body_RF12">
        <visual>
            <geometry>
                <mesh filename="package://hubo_kart_display_v1/meshes/convhull_RF12_merged.stl"/>
            </geometry>
            <origin rpy="0 0 0" xyz="0 0 0"/>
            <material name="">
                <color rgba="0.752941176471 0.752941176471 0.752941176471 1.0"/>
            </material>
        </visual>
        <collision>
            <geometry>
                <mesh filename="package://hubo_kart_display_v1/meshes/convhull_RF12_merged.stl"/>
            </geometry>
            <origin rpy="0 0 0" xyz="0 0 0"/>
        </collision>
        <inertial>
            <mass value="0.016189368249"/>
            <inertia ixx="1.30911370818e-06" ixy="1.49423602565e-08" ixz="-5.01486524729e-08" iyy="2.82043860524e-06" iyz="-2.8629444527e-09" izz="3.05888536891e-06"/>
            <origin rpy="0 0 0" xyz="0.0110393059886 0.000234060880175 5.56986057553e-05"/>
        </inertial>
    </link>
    <joint name="RF12" type="revolute">
        <parent link="Body_RF11"/>
        <child link="Body_RF12"/>
        <origin rpy="0 1.3963 0" xyz="0.041952 0 -0.002"/>
        <axis xyz="0 1.0 0"/>
        <limit effort="25" lower="-3.14159265359" upper="3.14159265359" velocity="6.28318530718"/>
    </joint>
    <link name="Body_RF13">
        <visual>
            <geometry>
                <mesh filename="package://hubo_kart_display_v1/meshes/convhull_RF13_merged.stl"/>
            </geometry>
            <origin rpy="0 0 0" xyz="0 0 0"/>
            <material name="">
                <color rgba="0.752941176471 0.752941176471 0.752941176471 1.0"/>
            </material>
        </visual>
        <collision>
            <geometry>
                <mesh filename="package://hubo_kart_display_v1/meshes/convhull_RF13_merged.stl"/>
            </geometry>
            <origin rpy="0 0 0" xyz="0 0 0"/>
        </collision>
        <inertial>
            <mass value="0.0182221650877"/>
            <inertia ixx="1.03181617487e-06" ixy="-4.94978359879e-08" ixz="-1.22492186704e-07" iyy="2.57254536616e-06" iyz="-5.58418574879e-09" izz="2.54656084717e-06"/>
            <origin rpy="0 0 0" xyz="0.0171497739791 -0.000431859131656 0.000224831410368"/>
        </inertial>
    </link>
    <joint name="RF13" type="revolute">
        <parent link="Body_RF12"/>
        <child link="Body_RF13"/>
        <origin rpy="0 1.3963 0" xyz="0.029967 0 -0.0014"/>
        <axis xyz="0 1.0 0"/>
        <limit effort="25" lower="-3.14159265359" upper="3.14159265359" velocity="6.28318530718"/>
    </joint>
    <link name="Body_RF21">
        <visual>
            <geometry>
                <mesh filename="package://hubo_kart_display_v1/meshes/convhull_RF11.stl"/>
            </geometry>
            <origin rpy="0 0 0" xyz="0 0 0"/>
            <material name="">
                <color rgba="0.752941176471 0.752941176471 0.752941176471 1.0"/>
            </material>
        </visual>
        <collision>
            <geometry>
                <mesh filename="package://hubo_kart_display_v1/meshes/convhull_RF11.stl"/>
            </geometry>
            <origin rpy="0 0 0" xyz="0 0 0"/>
        </collision>
        <inertial>
            <mass value="0.0263710648328"/>
            <inertia ixx="1.98396439062e-06" ixy="3.66951330319e-08" ixz="-7.82216813087e-08" iyy="6.90160086478e-06" iyz="-5.52885566501e-09" izz="6.59611827284e-06"/>
            <origin rpy="0 0 0" xyz="0.013675535045 0.000167665760228 0.000198749511991"/>
        </inertial>
    </link>
    <joint name="RF21" type="revolute">
        <parent link="Body_RWR"/>
        <child link="Body_RF21"/>
        <origin rpy="-1.5708 0 0" xyz="0.0875 0.026 3e-05"/>
        <axis xyz="0 0 -1.0"/>
        <limit effort="25" lower="-3.14159265359" upper="3.14159265359" velocity="6.28318530718"/>
    </joint>
    <link name="Body_RF22">
        <visual>
            <geometry>
                <mesh filename="package://hubo_kart_display_v1/meshes/convhull_RF12_merged.stl"/>
            </geometry>
            <origin rpy="0 0 0" xyz="0 0 0"/>
            <material name="">
                <color rgba="0.752941176471 0.752941176471 0.752941176471 1.0"/>
            </material>
        </visual>
        <collision>
            <geometry>
                <mesh filename="package://hubo_kart_display_v1/meshes/convhull_RF12_merged.stl"/>
            </geometry>
            <origin rpy="0 0 0" xyz="0 0 0"/>
        </collision>
        <inertial>
            <mass value="0.016189368249"/>
            <inertia ixx="1.30911370818e-06" ixy="1.49423602565e-08" ixz="-5.01486524729e-08" iyy="2.82043860524e-06" iyz="-2.8629444527e-09" izz="3.05888536891e-06"/>
            <origin rpy="0 0 0" xyz="0.0110393059886 0.000234060880175 5.56986057552e-05"/>
        </inertial>
    </link>
    <joint name="RF22" type="revolute">
        <parent link="Body_RF21"/>
        <child link="Body_RF22"/>
        <origin rpy="0 1.3963 0" xyz="0.041952 0 -0.002"/>
        <axis xyz="0 1.0 0"/>
        <limit effort="25" lower="-3.14159265359" upper="3.14159265359" velocity="6.28318530718"/>
    </joint>
    <link name="Body_RF23">
        <visual>
            <geometry>
                <mesh filename="package://hubo_kart_display_v1/meshes/convhull_RF13_merged.stl"/>
            </geometry>
            <origin rpy="0 0 0" xyz="0 0 0"/>
            <material name="">
                <color rgba="0.752941176471 0.752941176471 0.752941176471 1.0"/>
            </material>
        </visual>
        <collision>
            <geometry>
                <mesh filename="package://hubo_kart_display_v1/meshes/convhull_RF13_merged.stl"/>
            </geometry>
            <origin rpy="0 0 0" xyz="0 0 0"/>
        </collision>
        <inertial>
            <mass value="0.0182221650877"/>
            <inertia ixx="1.03181617487e-06" ixy="-4.94978359879e-08" ixz="-1.22492186704e-07" iyy="2.57254536616e-06" iyz="-5.58418574878e-09" izz="2.54656084717e-06"/>
            <origin rpy="0 0 0" xyz="0.0171497739791 -0.000431859131656 0.000224831410368"/>
        </inertial>
    </link>
    <joint name="RF23" type="revolute">
        <parent link="Body_RF22"/>
        <child link="Body_RF23"/>
        <origin rpy="0 1.3963 0" xyz="0.029967 0 -0.0014"/>
        <axis xyz="0 1.0 0"/>
        <limit effort="25" lower="-3.14159265359" upper="3.14159265359" velocity="6.28318530718"/>
    </joint>
    <link name="Body_RF31">
        <visual>
            <geometry>
                <mesh filename="package://hubo_kart_display_v1/meshes/convhull_RF11.stl"/>
            </geometry>
            <origin rpy="0 0 0" xyz="0 0 0"/>
            <material name="">
                <color rgba="0.752941176471 0.752941176471 0.752941176471 1.0"/>
            </material>
        </visual>
        <collision>
            <geometry>
                <mesh filename="package://hubo_kart_display_v1/meshes/convhull_RF11.stl"/>
            </geometry>
            <origin rpy="0 0 0" xyz="0 0 0"/>
        </collision>
        <inertial>
            <mass value="0.0263710648328"/>
            <inertia ixx="1.98396439062e-06" ixy="3.66951330319e-08" ixz="-7.82216813087e-08" iyy="6.90160086478e-06" iyz="-5.52885566502e-09" izz="6.59611827284e-06"/>
            <origin rpy="0 0 0" xyz="0.013675535045 0.000167665760228 0.000198749511991"/>
        </inertial>
    </link>
    <joint name="RF31" type="revolute">
        <parent link="Body_RWR"/>
        <child link="Body_RF31"/>
        <origin rpy="1.5708 0 0" xyz="0.0875 -0.026 -0.02247"/>
        <axis xyz="0 0 1.0"/>
        <limit effort="25" lower="-3.14159265359" upper="3.14159265359" velocity="6.28318530718"/>
    </joint>
    <link name="Body_RF32">
        <visual>
            <geometry>
                <mesh filename="package://hubo_kart_display_v1/meshes/convhull_RF12_merged.stl"/>
            </geometry>
            <origin rpy="0 0 0" xyz="0 0 0"/>
            <material name="">
                <color rgba="0.752941176471 0.752941176471 0.752941176471 1.0"/>
            </material>
        </visual>
        <collision>
            <geometry>
                <mesh filename="package://hubo_kart_display_v1/meshes/convhull_RF12_merged.stl"/>
            </geometry>
            <origin rpy="0 0 0" xyz="0 0 0"/>
        </collision>
        <inertial>
            <mass value="0.016189368249"/>
            <inertia ixx="1.30911370818e-06" ixy="1.49423602565e-08" ixz="-5.01486524729e-08" iyy="2.82043860524e-06" iyz="-2.8629444527e-09" izz="3.05888536891e-06"/>
            <origin rpy="0 0 0" xyz="0.0110393059886 0.000234060880175 5.56986057552e-05"/>
        </inertial>
    </link>
    <joint name="RF32" type="revolute">
        <parent link="Body_RF31"/>
        <child link="Body_RF32"/>
        <origin rpy="0 1.3963 0" xyz="0.041952 0 -0.002"/>
        <axis xyz="0 1.0 0"/>
        <limit effort="25" lower="-3.14159265359" upper="3.14159265359" velocity="6.28318530718"/>
    </joint>
    <link name="Body_RF33">
        <visual>
            <geometry>
                <mesh filename="package://hubo_kart_display_v1/meshes/convhull_RF13_merged.stl"/>
            </geometry>
            <origin rpy="0 0 0" xyz="0 0 0"/>
            <material name="">
                <color rgba="0.752941176471 0.752941176471 0.752941176471 1.0"/>
            </material>
        </visual>
        <collision>
            <geometry>
                <mesh filename="package://hubo_kart_display_v1/meshes/convhull_RF13_merged.stl"/>
            </geometry>
            <origin rpy="0 0 0" xyz="0 0 0"/>
        </collision>
        <inertial>
            <mass value="0.0182221650877"/>
            <inertia ixx="1.03181617487e-06" ixy="-4.94978359879e-08" ixz="-1.22492186704e-07" iyy="2.57254536616e-06" iyz="-5.58418574879e-09" izz="2.54656084717e-06"/>
            <origin rpy="0 0 0" xyz="0.0171497739791 -0.000431859131656 0.000224831410368"/>
        </inertial>
    </link>
    <joint name="RF33" type="revolute">
        <parent link="Body_RF32"/>
        <child link="Body_RF33"/>
        <origin rpy="0 1.3963 0" xyz="0.029967 0 -0.0014"/>
        <axis xyz="0 1.0 0"/>
        <limit effort="25" lower="-3.14159265359" upper="3.14159265359" velocity="6.28318530718"/>
    </joint>
    <link name="Body_LSP">
        <visual>
            <geometry>
                <mesh filename="package://hubo_kart_display_v1/meshes/convhull_LSP_merged.stl"/>
            </geometry>
            <origin rpy="0 0 0" xyz="0 0 0"/>
            <material name="">
                <color rgba="0.752941176471 0.752941176471 0.752941176471 1.0"/>
            </material>
        </visual>
        <collision>
            <geometry>
                <mesh filename="package://hubo_kart_display_v1/meshes/convhull_LSP_merged.stl"/>
            </geometry>
            <origin rpy="0 0 0" xyz="0 0 0"/>
        </collision>
        <inertial>
            <mass value="0.925752239669"/>
            <inertia ixx="0.00168445461162" ixy="0.000340206078138" ixz="-6.31660338214e-06" iyy="0.00157378126325" iyz="-7.95927300515e-06" izz="0.00244770101015"/>
            <origin rpy="0 0 0" xyz="0.0211206130677 0.0669651647046 0.000177534129465"/>
        </inertial>
    </link>
    <link name="Body_LSR">
        <visual>
            <geometry>
                <mesh filename="package://hubo_kart_display_v1/meshes/convhull_LSR_merged.stl"/>
            </geometry>
            <origin rpy="0 0 0" xyz="0 0 0"/>
            <material name="">
                <color rgba="0.752941176471 0.752941176471 0.752941176471 1.0"/>
            </material>
        </visual>
        <collision>
            <geometry>
                <mesh filename="package://hubo_kart_display_v1/meshes/convhull_LSR_merged.stl"/>
            </geometry>
            <origin rpy="0 0 0" xyz="0 0 0"/>
        </collision>
        <inertial>
            <mass value="0.772866145701"/>
            <inertia ixx="0.000583426982031" ixy="-8.46801592608e-07" ixz="-3.33711094992e-05" iyy="0.000797704704735" iyz="1.1857891966e-05" izz="0.000561294586058"/>
            <origin rpy="0 0 0" xyz="-0.0375650279693 -0.000356075210703 -0.0117791110906"/>
        </inertial>
    </link>
    <link name="Body_LSY">
        <visual>
            <geometry>
                <mesh filename="package://hubo_kart_display_v1/meshes/convhull_LSY_merged.stl"/>
            </geometry>
            <origin rpy="0 0 0" xyz="0 0 0"/>
            <material name="">
                <color rgba="0.752941176471 0.752941176471 0.752941176471 1.0"/>
            </material>
        </visual>
        <collision>
            <geometry>
                <mesh filename="package://hubo_kart_display_v1/meshes/convhull_LSY_merged.stl"/>
            </geometry>
            <origin rpy="0 0 0" xyz="0 0 0"/>
        </collision>
        <inertial>
            <mass value="2.05731646102"/>
            <inertia ixx="0.0223084392611" ixy="-2.50613568022e-05" ixz="-0.00188493824891" iyy="0.0224224037845" iyz="0.000332193108806" izz="0.00158588979968"/>
            <origin rpy="0 0 0" xyz="0.00919437021309 -0.00191434175871 -0.169537229579"/>
        </inertial>
    </link>
    <link name="Body_LEP">
        <visual>
            <geometry>
                <mesh filename="package://hubo_kart_display_v1/meshes/convhull_LEP_merged.stl"/>
            </geometry>
            <origin rpy="0 0 0" xyz="0 0 0"/>
            <material name="">
                <color rgba="0.752941176471 0.752941176471 0.752941176471 1.0"/>
            </material>
        </visual>
        <collision>
            <geometry>
                <mesh filename="package://hubo_kart_display_v1/meshes/convhull_LEP_merged.stl"/>
            </geometry>
            <origin rpy="0 0 0" xyz="0 0 0"/>
        </collision>
        <inertial>
            <mass value="0.298170328162"/>
            <inertia ixx="0.000394363251821" ixy="-1.34384975568e-06" ixz="7.57996574577e-05" iyy="0.000374815280261" iyz="2.18982902478e-06" izz="0.000273941918371"/>
            <origin rpy="0 0 0" xyz="-0.0244460480201 -0.0182798518231 -0.0396913386769"/>
        </inertial>
    </link>
    <link name="Body_LWY">
        <visual>
            <geometry>
                <mesh filename="package://hubo_kart_display_v1/meshes/convhull_LWY_merged.stl"/>
            </geometry>
            <origin rpy="0 0 0" xyz="0 0 0"/>
            <material name="">
                <color rgba="0.752941176471 0.752941176471 0.752941176471 1.0"/>
            </material>
        </visual>
        <collision>
            <geometry>
                <mesh filename="package://hubo_kart_display_v1/meshes/convhull_LWY_merged.stl"/>
            </geometry>
            <origin rpy="0 0 0" xyz="0 0 0"/>
        </collision>
        <inertial>
            <mass value="1.68933309958"/>
            <inertia ixx="0.0176540649275" ixy="-3.61034488579e-06" ixz="8.37319577754e-06" iyy="0.0150234017716" iyz="-0.00516603192566" izz="0.00331146614296"/>
            <origin rpy="0 0 0" xyz="3.39374071556e-05 0.0559979630014 -0.151262292453"/>
        </inertial>
    </link>
    <link name="Body_LWP">
        <visual>
            <geometry>
                <mesh filename="package://hubo_kart_display_v1/meshes/convhull_LWP_merged.stl"/>
            </geometry>
            <origin rpy="0 0 0" xyz="0 0 0"/>
            <material name="">
                <color rgba="0.752941176471 0.752941176471 0.752941176471 1.0"/>
            </material>
        </visual>
        <collision>
            <geometry>
                <mesh filename="package://hubo_kart_display_v1/meshes/convhull_LWP_merged.stl"/>
            </geometry>
            <origin rpy="0 0 0" xyz="0 0 0"/>
        </collision>
        <inertial>
            <mass value="0.327632198289"/>
            <inertia ixx="0.000346968656319" ixy="5.89262498623e-05" ixz="4.30826482069e-06" iyy="0.00057562979027" iyz="-1.25504736046e-06" izz="0.000744124634836"/>
            <origin rpy="0 0 0" xyz="-0.0145320131223 -0.0546994779181 -0.000367800192129"/>
        </inertial>
    </link>
    <link name="Body_LWR">
        <visual>
            <geometry>
                <mesh filename="package://hubo_kart_display_v1/meshes/convhull_LWR_merged.stl"/>
            </geometry>
            <origin rpy="0 0 0" xyz="0 0 0"/>
            <material name="">
                <color rgba="0.752941176471 0.752941176471 0.752941176471 1.0"/>
            </material>
        </visual>
        <collision>
            <geometry>
                <mesh filename="package://hubo_kart_display_v1/meshes/convhull_LWR_merged.stl"/>
            </geometry>
            <origin rpy="0 0 0" xyz="0 0 0"/>
        </collision>
        <inertial>
            <mass value="1.26227162553"/>
            <inertia ixx="0.00137019038629" ixy="6.08173568367e-05" ixz="5.84193124812e-06" iyy="0.00133077281236" iyz="-1.17164831963e-05" izz="0.00120357514264"/>
            <origin rpy="0 0 0" xyz="0.0461316332402 -0.000476271776753 0.0008021254173"/>
        </inertial>
    </link>
    <link name="leftPalm">
        <inertial>
            <mass value="0.1"/>
            <inertia ixx="0.0001" ixy="0" ixz="0" iyy="0.0001" iyz="0" izz="0.0001"/>
            <origin rpy="0 0 0" xyz="0 0 0"/>
        </inertial>
    </link>
    <joint name="LSP" type="revolute">
        <parent link="Body_Torso"/>
        <child link="Body_LSP"/>
        <origin rpy="0 0 0" xyz="0 0.1435 0"/>
        <axis xyz="0 1.0 0"/>
        <limit effort="25" lower="-3.7843248114" upper="3.75549755721" velocity="6.28318530718"/>
    </joint>
    <joint name="LSR" type="revolute">
        <parent link="Body_LSP"/>
        <child link="Body_LSR"/>
        <origin rpy="0 0 0" xyz="0.033 0.086 0"/>
        <axis xyz="1.0 0 0"/>
        <limit effort="25" lower="-0.61813977052" upper="3.15177141379" velocity="6.28318530718"/>
    </joint>
    <joint name="LSY" type="revolute">
        <parent link="Body_LSR"/>
        <child link="Body_LSY"/>
        <origin rpy="0 0 0" xyz="-0.033 0 -0.027"/>
        <axis xyz="0 0 1.0"/>
        <limit effort="25" lower="-2.90646015143" upper="2.90548625771" velocity="6.28318530718"/>
    </joint>
    <joint name="LEP" type="revolute">
        <parent link="Body_LSY"/>
        <child link="Body_LEP"/>
        <origin rpy="0 0 0" xyz="0.03 0.019 -0.273"/>
        <axis xyz="0 1.0 0"/>
        <limit effort="25" lower="-2.32516340876" upper="0.682911557056" velocity="6.28318530718"/>
    </joint>
    <joint name="LWY" type="revolute">
        <parent link="Body_LEP"/>
        <child link="Body_LWY"/>
        <origin rpy="0 0 0" xyz="-0.03 -0.019 -0.052"/>
        <axis xyz="0 0 1.0"/>
        <limit effort="25" lower="-2.8506654659" upper="2.77278538402" velocity="6.28318530718"/>
    </joint>
    <joint name="LWP" type="revolute">
        <parent link="Body_LWY"/>
        <child link="Body_LWP"/>
        <origin rpy="0 1.57079632679 0" xyz="0 0.067 -0.2618"/>
        <axis xyz="0 1.0 0"/>
        <limit effort="25" lower="-3.28246952216" upper="2.13677780528" velocity="6.28318530718"/>
    </joint>
    <joint name="LWR" type="revolute">
        <parent link="Body_LWP"/>
        <child link="Body_LWR"/>
        <origin rpy="0 0 0" xyz="0.027 -0.067 0"/>
        <axis xyz="-1.0 0 0"/>
        <limit effort="25" lower="-2.69956074975" upper="2.7000516236" velocity="6.28318530718"/>
    </joint>
    <joint name="LWR_dummy" type="fixed">
        <parent link="Body_LWR"/>
        <child link="leftPalm"/>
        <origin rpy="0 0 1.57079632679" xyz="0.1 0 0"/>
    </joint>
    <link name="Body_LHY">
        <visual>
            <geometry>
                <mesh filename="package://hubo_kart_display_v1/meshes/convhull_LHY_merged.stl"/>
            </geometry>
            <origin rpy="0 0 0" xyz="0 0 0"/>
            <material name="">
                <color rgba="0.752941176471 0.752941176471 0.752941176471 1.0"/>
            </material>
        </visual>
        <collision>
            <geometry>
                <mesh filename="package://hubo_kart_display_v1/meshes/convhull_LHY_merged.stl"/>
            </geometry>
            <origin rpy="0 0 0" xyz="0 0 0"/>
        </collision>
        <inertial>
            <mass value="1.39676631505"/>
            <inertia ixx="0.00288796936083" ixy="-9.31467192308e-07" ixz="-0.00107856005839" iyy="0.00475787075044" iyz="1.27885368145e-06" izz="0.0030062595856"/>
            <origin rpy="0 0 0" xyz="0.0357455188333 9.87014023897e-06 -0.0612768789732"/>
        </inertial>
    </link>
    <link name="Body_LHR">
        <visual>
            <geometry>
                <mesh filename="package://hubo_kart_display_v1/meshes/convhull_LHR_merged.stl"/>
            </geometry>
            <origin rpy="0 0 0" xyz="0 0 0"/>
            <material name="">
                <color rgba="0.752941176471 0.752941176471 0.752941176471 1.0"/>
            </material>
        </visual>
        <collision>
            <geometry>
                <mesh filename="package://hubo_kart_display_v1/meshes/convhull_LHR_merged.stl"/>
            </geometry>
            <origin rpy="0 0 0" xyz="0 0 0"/>
        </collision>
        <inertial>
            <mass value="1.87327014692"/>
            <inertia ixx="0.00271708242471" ixy="-6.95355289452e-06" ixz="-0.000124506400405" iyy="0.00314352531524" iyz="0.000179044888416" izz="0.00241624814317"/>
            <origin rpy="0 0 0" xyz="-0.0546751887964 -0.000755923439321 -0.0250478918092"/>
        </inertial>
    </link>
    <link name="Body_LHP">
        <visual>
            <geometry>
                <mesh filename="package://hubo_kart_display_v1/meshes/convhull_LHP_merged.stl"/>
            </geometry>
            <origin rpy="0 0 0" xyz="0 0 0"/>
            <material name="">
                <color rgba="0.752941176471 0.752941176471 0.752941176471 1.0"/>
            </material>
        </visual>
        <collision>
            <geometry>
                <mesh filename="package://hubo_kart_display_v1/meshes/convhull_LHP_merged.stl"/>
            </geometry>
            <origin rpy="0 0 0" xyz="0 0 0"/>
        </collision>
        <inertial>
            <mass value="4.08210586511"/>
            <inertia ixx="0.0731344926009" ixy="-0.000774522574823" ixz="-0.00133507444321" iyy="0.0704116135206" iyz="0.0038008172567" izz="0.0104352186397"/>
            <origin rpy="0 0 0" xyz="0.014307872736 -0.0329553894437 -0.191508079337"/>
        </inertial>
    </link>
    <link name="Body_LKP">
        <visual>
            <geometry>
                <mesh filename="package://hubo_kart_display_v1/meshes/convhull_LKP_merged.stl"/>
            </geometry>
            <origin rpy="0 0 0" xyz="0 0 0"/>
            <material name="">
                <color rgba="0.75294 0.75294 0.75294 1.0"/>
            </material>
        </visual>
        <collision>
            <geometry>
                <mesh filename="package://hubo_kart_display_v1/meshes/convhull_LKP_merged.stl"/>
            </geometry>
            <origin rpy="0 0 0" xyz="0 0 0"/>
        </collision>
        <inertial>
            <mass value="1.5575"/>
            <inertia ixx="0.023902" ixy="0.00016341" ixz="0.0003317" iyy="0.021931" iyz="0.00047965" izz="0.0043485"/>
            <origin rpy="0 0 0" xyz="0.015377 -0.023243 -0.16683"/>
        </inertial>
    </link>
    <link name="Body_LAP">
        <visual>
            <geometry>
                <mesh filename="package://hubo_kart_display_v1/meshes/convhull_LAP_merged.stl"/>
            </geometry>
            <origin rpy="0 0 0" xyz="0 0 0"/>
            <material name="">
                <color rgba="0.752941176471 0.752941176471 0.752941176471 1.0"/>
            </material>
        </visual>
        <collision>
            <geometry>
                <mesh filename="package://hubo_kart_display_v1/meshes/convhull_LAP_merged.stl"/>
            </geometry>
            <origin rpy="0 0 0" xyz="0 0 0"/>
        </collision>
        <inertial>
            <mass value="2.28752729358"/>
            <inertia ixx="0.00372279383771" ixy="-0.000408405026298" ixz="-0.000324861356781" iyy="0.00395779600552" iyz="-0.000345535189408" izz="0.00437930917038"/>
            <origin rpy="0 0 0" xyz="0.015517139691 -0.0515086693793 0.00905289185767"/>
        </inertial>
    </link>
    <link name="Body_LAR">
        <visual>
            <geometry>
                <mesh filename="package://hubo_kart_display_v1/meshes/convhull_LAR_merged.stl"/>
            </geometry>
            <origin rpy="0 0 0" xyz="0 0 0"/>
            <material name="">
                <color rgba="0.75294 0.75294 0.75294 1.0"/>
            </material>
        </visual>
        <collision>
            <geometry>
                <mesh filename="package://hubo_kart_display_v1/meshes/convhull_LAR_merged.stl"/>
            </geometry>
            <origin rpy="0 0 0" xyz="0 0 0"/>
        </collision>
        <inertial>
            <mass value="1.173"/>
            <inertia ixx="0.0040657" ixy="3.062e-05" ixz="-0.0002436" iyy="0.0066321" iyz="-0.00010311" izz="0.00448"/>
            <origin rpy="0 0 0" xyz="-0.053052 0.0019082 -0.093274"/>
        </inertial>
    </link>
    <link name="leftFoot">
        <inertial>
            <mass value="0.1"/>
            <inertia ixx="0.0001" ixy="0" ixz="0" iyy="0.0001" iyz="0" izz="0.0001"/>
            <origin rpy="0 0 0" xyz="0 0 0"/>
        </inertial>
    </link>

 


    <joint name="LHY" type="revolute">
        <parent link="Body_TSY"/>
        <child link="Body_LHY"/>
        <origin rpy="0 0 0" xyz="0 0.0885 -0.0751"/>
        <axis xyz="0 0 1.0"/>
        <limit effort="25" lower="-1.57079004361" upper="2.38761669991" velocity="6.28318530718"/>
    </joint>
    <joint name="LHR" type="revolute">
        <parent link="Body_LHY"/>
        <child link="Body_LHR"/>
        <origin rpy="0 0 0" xyz="0.052 0 -0.091"/>
        <axis xyz="1.0 0 0"/>
        <limit effort="25" lower="-0.372754225145" upper="0.559139103495" velocity="6.28318530718"/>
    </joint>
    <joint name="LHP" type="revolute">
        <parent link="Body_LHR"/>
        <child link="Body_LHP"/>
        <origin rpy="0 0 0" xyz="-0.052 0.0445 0"/>
        <axis xyz="0 1.0 0"/>
        <limit effort="25" lower="-1.85507119204" upper="1.60068072691" velocity="6.28318530718"/>
    </joint>
    <joint name="LKP" type="revolute">
        <parent link="Body_LHP"/>
        <child link="Body_LKP"/>
        <origin rpy="0 0 0" xyz="0 -0.0285 -0.33"/>
        <axis xyz="0 1.0 0"/>
        <limit effort="25" lower="-0.765758104224" upper="2.70570177799" velocity="6.28318530718"/>
    </joint>
    <joint name="LAP" type="revolute">
        <parent link="Body_LKP"/>
        <child link="Body_LAP"/>
        <origin rpy="0 0 0" xyz="0 0.047 -0.33"/>
        <axis xyz="0 1.0 0"/>
        <limit effort="25" lower="-1.64333570117" upper="2.25223918929" velocity="6.28318530718"/>
    </joint>
    <joint name="LAR" type="revolute">
        <parent link="Body_LAP"/>
        <child link="Body_LAR"/>
        <origin rpy="0 0 0" xyz="0.0705 -0.063 0"/>
        <axis xyz="1.0 0 0"/>
        <limit effort="25" lower="-1.73952924336" upper="1.73953918356" velocity="6.28318530718"/>
    </joint>
    <joint name="LAR_dummy" type="fixed">
        <parent link="Body_LAR"/>
        <child link="leftFoot"/>
        <origin rpy="0 0 0" xyz="0 0 -0.1371"/>
    </joint>
    <link name="Body_LF11">
        <visual>
            <geometry>
                <mesh filename="package://hubo_kart_display_v1/meshes/convhull_LF11.stl"/>
            </geometry>
            <origin rpy="0 0 0" xyz="0 0 0"/>
            <material name="">
                <color rgba="0.752941176471 0.752941176471 0.752941176471 1.0"/>
            </material>
        </visual>
        <collision>
            <geometry>
                <mesh filename="package://hubo_kart_display_v1/meshes/convhull_LF11.stl"/>
            </geometry>
            <origin rpy="0 0 0" xyz="0 0 0"/>
        </collision>
        <inertial>
            <mass value="0.0263710648328"/>
            <inertia ixx="1.98396439062e-06" ixy="3.66951330319e-08" ixz="-7.82216813087e-08" iyy="6.90160086478e-06" iyz="-5.52885566501e-09" izz="6.59611827284e-06"/>
            <origin rpy="0 0 0" xyz="0.013675535045 0.000167665760228 0.000198749511991"/>
        </inertial>
    </link>
    <link name="Body_LF12">
        <visual>
            <geometry>
                <mesh filename="package://hubo_kart_display_v1/meshes/convhull_LF12_merged.stl"/>
            </geometry>
            <origin rpy="0 0 0" xyz="0 0 0"/>
            <material name="">
                <color rgba="0.752941176471 0.752941176471 0.752941176471 1.0"/>
            </material>
        </visual>
        <collision>
            <geometry>
                <mesh filename="package://hubo_kart_display_v1/meshes/convhull_LF12_merged.stl"/>
            </geometry>
            <origin rpy="0 0 0" xyz="0 0 0"/>
        </collision>
        <inertial>
            <mass value="0.016189368249"/>
            <inertia ixx="1.30911370818e-06" ixy="1.49423602565e-08" ixz="-5.01486524729e-08" iyy="2.82043860524e-06" iyz="-2.8629444527e-09" izz="3.05888536891e-06"/>
            <origin rpy="0 0 0" xyz="0.0110393059886 0.000234060880175 5.56986057553e-05"/>
        </inertial>
    </link>
    <link name="Body_LF13">
        <visual>
            <geometry>
                <mesh filename="package://hubo_kart_display_v1/meshes/convhull_LF13_merged.stl"/>
            </geometry>
            <origin rpy="0 0 0" xyz="0 0 0"/>
            <material name="">
                <color rgba="0.752941176471 0.752941176471 0.752941176471 1.0"/>
            </material>
        </visual>
        <collision>
            <geometry>
                <mesh filename="package://hubo_kart_display_v1/meshes/convhull_LF13_merged.stl"/>
            </geometry>
            <origin rpy="0 0 0" xyz="0 0 0"/>
        </collision>
        <inertial>
            <mass value="0.0182221650877"/>
            <inertia ixx="1.03181617487e-06" ixy="-4.94978359879e-08" ixz="-1.22492186704e-07" iyy="2.57254536616e-06" iyz="-5.58418574879e-09" izz="2.54656084717e-06"/>
            <origin rpy="0 0 0" xyz="0.0171497739791 -0.000431859131656 0.000224831410368"/>
        </inertial>
    </link>
    <joint name="LF1" type="revolute">
        <parent link="Body_LWR"/>
        <child link="Body_LF11"/>
        <origin rpy="4.71239265359 0 0" xyz="0.0875 0.026 0.02247"/>
        <axis xyz="0 0 -1.0"/>
        <limit effort="25" lower="-1.85349620283" upper="0.2" velocity="6.28318530718"/>
    </joint>
    <joint name="LF12" type="revolute">
        <parent link="Body_LF11"/>
        <child link="Body_LF12"/>
        <origin rpy="0 1.3963 0" xyz="0.041952 0 -0.002"/>
        <axis xyz="0 1.0 0"/>
        <limit effort="25" lower="-3.14159265359" upper="3.14159265359" velocity="6.28318530718"/>
    </joint>
    <joint name="LF13" type="revolute">
        <parent link="Body_LF12"/>
        <child link="Body_LF13"/>
        <origin rpy="0 1.3963 0" xyz="0.029967 0 -0.0014"/>
        <axis xyz="0 1.0 0"/>
        <limit effort="25" lower="-3.14159265359" upper="3.14159265359" velocity="6.28318530718"/>
    </joint>
    <link name="Body_LF21">
        <visual>
            <geometry>
                <mesh filename="package://hubo_kart_display_v1/meshes/convhull_LF11.stl"/>
            </geometry>
            <origin rpy="0 0 0" xyz="0 0 0"/>
            <material name="">
                <color rgba="0.752941176471 0.752941176471 0.752941176471 1.0"/>
            </material>
        </visual>
        <collision>
            <geometry>
                <mesh filename="package://hubo_kart_display_v1/meshes/convhull_LF11.stl"/>
            </geometry>
            <origin rpy="0 0 0" xyz="0 0 0"/>
        </collision>
        <inertial>
            <mass value="0.0263710648328"/>
            <inertia ixx="1.98396439062e-06" ixy="3.66951330319e-08" ixz="-7.82216813087e-08" iyy="6.90160086478e-06" iyz="-5.52885566501e-09" izz="6.59611827284e-06"/>
            <origin rpy="0 0 0" xyz="0.013675535045 0.000167665760228 0.000198749511991"/>
        </inertial>
    </link>
    <link name="Body_LF22">
        <visual>
            <geometry>
                <mesh filename="package://hubo_kart_display_v1/meshes/convhull_LF12_merged.stl"/>
            </geometry>
            <origin rpy="0 0 0" xyz="0 0 0"/>
            <material name="">
                <color rgba="0.752941176471 0.752941176471 0.752941176471 1.0"/>
            </material>
        </visual>
        <collision>
            <geometry>
                <mesh filename="package://hubo_kart_display_v1/meshes/convhull_LF12_merged.stl"/>
            </geometry>
            <origin rpy="0 0 0" xyz="0 0 0"/>
        </collision>
        <inertial>
            <mass value="0.016189368249"/>
            <inertia ixx="1.30911370818e-06" ixy="1.49423602565e-08" ixz="-5.01486524729e-08" iyy="2.82043860524e-06" iyz="-2.8629444527e-09" izz="3.05888536891e-06"/>
            <origin rpy="0 0 0" xyz="0.0110393059886 0.000234060880175 5.56986057552e-05"/>
        </inertial>
    </link>
    <link name="Body_LF23">
        <visual>
            <geometry>
                <mesh filename="package://hubo_kart_display_v1/meshes/convhull_LF13_merged.stl"/>
            </geometry>
            <origin rpy="0 0 0" xyz="0 0 0"/>
            <material name="">
                <color rgba="0.752941176471 0.752941176471 0.752941176471 1.0"/>
            </material>
        </visual>
        <collision>
            <geometry>
                <mesh filename="package://hubo_kart_display_v1/meshes/convhull_LF13_merged.stl"/>
            </geometry>
            <origin rpy="0 0 0" xyz="0 0 0"/>
        </collision>
        <inertial>
            <mass value="0.0182221650877"/>
            <inertia ixx="1.03181617487e-06" ixy="-4.94978359879e-08" ixz="-1.22492186704e-07" iyy="2.57254536616e-06" iyz="-5.58418574878e-09" izz="2.54656084717e-06"/>
            <origin rpy="0 0 0" xyz="0.0171497739791 -0.000431859131656 0.000224831410368"/>
        </inertial>
    </link>
    <joint name="LF21" type="revolute">
        <parent link="Body_LWR"/>
        <child link="Body_LF21"/>
        <origin rpy="1.57079265359 0 0" xyz="0.0875 -0.026 3e-05"/>
        <axis xyz="0 0 1.0"/>
        <limit effort="25" lower="-3.14159265359" upper="3.14159265359" velocity="6.28318530718"/>
    </joint>
    <joint name="LF22" type="revolute">
        <parent link="Body_LF21"/>
        <child link="Body_LF22"/>
        <origin rpy="0 1.3963 0" xyz="0.041952 0 -0.002"/>
        <axis xyz="0 1.0 0"/>
        <limit effort="25" lower="-3.14159265359" upper="3.14159265359" velocity="6.28318530718"/>
    </joint>
    <joint name="LF23" type="revolute">
        <parent link="Body_LF22"/>
        <child link="Body_LF23"/>
        <origin rpy="0 1.3963 0" xyz="0.029967 0 -0.0014"/>
        <axis xyz="0 1.0 0"/>
        <limit effort="25" lower="-3.14159265359" upper="3.14159265359" velocity="6.28318530718"/>
    </joint>
    <link name="Body_LF31">
        <visual>
            <geometry>
                <mesh filename="package://hubo_kart_display_v1/meshes/convhull_LF11.stl"/>
            </geometry>
            <origin rpy="0 0 0" xyz="0 0 0"/>
            <material name="">
                <color rgba="0.752941176471 0.752941176471 0.752941176471 1.0"/>
            </material>
        </visual>
        <collision>
            <geometry>
                <mesh filename="package://hubo_kart_display_v1/meshes/convhull_LF11.stl"/>
            </geometry>
            <origin rpy="0 0 0" xyz="0 0 0"/>
        </collision>
        <inertial>
            <mass value="0.0263710648328"/>
            <inertia ixx="1.98396439062e-06" ixy="3.66951330319e-08" ixz="-7.82216813087e-08" iyy="6.90160086478e-06" iyz="-5.52885566502e-09" izz="6.59611827284e-06"/>
            <origin rpy="0 0 0" xyz="0.013675535045 0.000167665760228 0.000198749511991"/>
        </inertial>
    </link>
    <link name="Body_LF32">
        <visual>
            <geometry>
                <mesh filename="package://hubo_kart_display_v1/meshes/convhull_LF12_merged.stl"/>
            </geometry>
            <origin rpy="0 0 0" xyz="0 0 0"/>
            <material name="">
                <color rgba="0.752941176471 0.752941176471 0.752941176471 1.0"/>
            </material>
        </visual>
        <collision>
            <geometry>
                <mesh filename="package://hubo_kart_display_v1/meshes/convhull_LF12_merged.stl"/>
            </geometry>
            <origin rpy="0 0 0" xyz="0 0 0"/>
        </collision>
        <inertial>
            <mass value="0.016189368249"/>
            <inertia ixx="1.30911370818e-06" ixy="1.49423602565e-08" ixz="-5.01486524729e-08" iyy="2.82043860524e-06" iyz="-2.8629444527e-09" izz="3.05888536891e-06"/>
            <origin rpy="0 0 0" xyz="0.0110393059886 0.000234060880175 5.56986057552e-05"/>
        </inertial>
    </link>
    <link name="Body_LF33">
        <visual>
            <geometry>
                <mesh filename="package://hubo_kart_display_v1/meshes/convhull_LF13_merged.stl"/>
            </geometry>
            <origin rpy="0 0 0" xyz="0 0 0"/>
            <material name="">
                <color rgba="0.752941176471 0.752941176471 0.752941176471 1.0"/>
            </material>
        </visual>
        <collision>
            <geometry>
                <mesh filename="package://hubo_kart_display_v1/meshes/convhull_LF13_merged.stl"/>
            </geometry>
            <origin rpy="0 0 0" xyz="0 0 0"/>
        </collision>
        <inertial>
            <mass value="0.0182221650877"/>
            <inertia ixx="1.03181617487e-06" ixy="-4.94978359879e-08" ixz="-1.22492186704e-07" iyy="2.57254536616e-06" iyz="-5.58418574879e-09" izz="2.54656084717e-06"/>
            <origin rpy="0 0 0" xyz="0.0171497739791 -0.000431859131656 0.000224831410368"/>
        </inertial>
    </link>
    <joint name="LF31" type="revolute">
        <parent link="Body_LWR"/>
        <child link="Body_LF31"/>
        <origin rpy="4.71239265359 0 0" xyz="0.0875 0.026 -0.02247"/>
        <axis xyz="0 0 -1.0"/>
        <limit effort="25" lower="-3.14159265359" upper="3.14159265359" velocity="6.28318530718"/>
    </joint>
    <joint name="LF32" type="revolute">
        <parent link="Body_LF31"/>
        <child link="Body_LF32"/>
        <origin rpy="0 1.3963 0" xyz="0.041952 0 -0.002"/>
        <axis xyz="0 1.0 0"/>
        <limit effort="25" lower="-3.14159265359" upper="3.14159265359" velocity="6.28318530718"/>
    </joint>
    <joint name="LF33" type="revolute">
        <parent link="Body_LF32"/>
        <child link="Body_LF33"/>
        <origin rpy="0 1.3963 0" xyz="0.029967 0 -0.0014"/>
        <axis xyz="0 1.0 0"/>
        <limit effort="25" lower="-3.14159265359" upper="3.14159265359" velocity="6.28318530718"/>
    </joint>



</robot>
