<?xml version="1.0" ?>
<robot name="PolarisRanger900XP">
  
 <link name="polaris_base">
    <visual>
      <geometry>
        <cylinder length="0.0" radius="0.0"/>
      </geometry>
    </visual>
  </link>

  
<link name="polaris_Chassis">
 <visual>
 <geometry>
<mesh filename="package://PolarisRanger900XP/meshes/polarischassis.stl" />
 </geometry>

<material name="">
 <color rgba="0.3 0 0.7 1" />
</material>
</visual>
    
<collision>
 <origin
  xyz="0 0 0"
  rpy="0 0 0" />
<geometry>
    <mesh
          filename="package://PolarisRanger900XP/meshes/polarischassis.stl" />
      </geometry>
    </collision>
  </link>

<joint name="polaris_move" type="planar">
        <parent link="polaris_base"/>
        <child link="polaris_Chassis"/>
        <origin rpy="0 0 0" xyz="0.0 0 0.0"/>
        <axis xyz="0 0 1.0"/>
      <limit effort="25" lower="-1.06813521904" upper="1.06814778541" velocity="6.28318530718"/>  
    </joint>

</robot>
